2025-04-24 03:19:40,504 - [ERROR] -  src.handlers.menu - (menu.py).menu(35) - <_InactiveRpcError of RPC that terminated with:
	status = StatusCode.UNKNOWN
	details = "Unexpected <class 'minio.error.S3Error'>: S3 operation failed; code: NoSuchKey, message: The specified key does not exist., resource: /profiles-images/426ec06d-61f7-4d84-8b27-d952743d9bab_1745464780472_0.jpg, 426ec06d-61f7-4d84-8b27-d952743d9bab_1745464780481_1.jpg, 426ec06d-61f7-4d84-8b27-d952743d9bab_1745464780487_2.jpg, request_id: 183922F851DDAF46, host_id: dd9025bab4ad464b049177c95eb6ebf374d3b3fd1af9251148b658df7ac2e3e8, bucket_name: profiles-images, object_name: 426ec06d-61f7-4d84-8b27-d952743d9bab_1745464780472_0.jpg, 426ec06d-61f7-4d84-8b27-d952743d9bab_1745464780481_1.jpg, 426ec06d-61f7-4d84-8b27-d952743d9bab_1745464780487_2.jpg"
	debug_error_string = "UNKNOWN:Error received from peer  {created_time:"2025-04-24T03:19:40.504735367+00:00", grpc_status:2, grpc_message:"Unexpected <class \'minio.error.S3Error\'>: S3 operation failed; code: NoSuchKey, message: The specified key does not exist., resource: /profiles-images/426ec06d-61f7-4d84-8b27-d952743d9bab_1745464780472_0.jpg, 426ec06d-61f7-4d84-8b27-d952743d9bab_1745464780481_1.jpg, 426ec06d-61f7-4d84-8b27-d952743d9bab_1745464780487_2.jpg, request_id: 183922F851DDAF46, host_id: dd9025bab4ad464b049177c95eb6ebf374d3b3fd1af9251148b658df7ac2e3e8, bucket_name: profiles-images, object_name: 426ec06d-61f7-4d84-8b27-d952743d9bab_1745464780472_0.jpg, 426ec06d-61f7-4d84-8b27-d952743d9bab_1745464780481_1.jpg, 426ec06d-61f7-4d84-8b27-d952743d9bab_1745464780487_2.jpg"}"
>
Traceback (most recent call last):
  File "/usr/src/dating/bot_service/src/handlers/menu.py", line 30, in menu
    profile_data = await profiles_connection.get_by_account_id(account_id)
                   ^^^^^^^^^^^^^^^^^^^^^^^^^^^^^^^^^^^^^^^^^^^^^^^^^^^^^^^
  File "/usr/src/dating/bot_service/src/api/grpc/connections/profiles.py", line 66, in get_by_account_id
    return self.stub.Get(profile_request)
           ^^^^^^^^^^^^^^^^^^^^^^^^^^^^^^
  File "/usr/local/lib/python3.12/site-packages/grpc/_channel.py", line 1181, in __call__
    return _end_unary_response_blocking(state, call, False, None)
           ^^^^^^^^^^^^^^^^^^^^^^^^^^^^^^^^^^^^^^^^^^^^^^^^^^^^^^
  File "/usr/local/lib/python3.12/site-packages/grpc/_channel.py", line 1006, in _end_unary_response_blocking
    raise _InactiveRpcError(state)  # pytype: disable=not-instantiable
    ^^^^^^^^^^^^^^^^^^^^^^^^^^^^^^
grpc._channel._InactiveRpcError: <_InactiveRpcError of RPC that terminated with:
	status = StatusCode.UNKNOWN
	details = "Unexpected <class 'minio.error.S3Error'>: S3 operation failed; code: NoSuchKey, message: The specified key does not exist., resource: /profiles-images/426ec06d-61f7-4d84-8b27-d952743d9bab_1745464780472_0.jpg, 426ec06d-61f7-4d84-8b27-d952743d9bab_1745464780481_1.jpg, 426ec06d-61f7-4d84-8b27-d952743d9bab_1745464780487_2.jpg, request_id: 183922F851DDAF46, host_id: dd9025bab4ad464b049177c95eb6ebf374d3b3fd1af9251148b658df7ac2e3e8, bucket_name: profiles-images, object_name: 426ec06d-61f7-4d84-8b27-d952743d9bab_1745464780472_0.jpg, 426ec06d-61f7-4d84-8b27-d952743d9bab_1745464780481_1.jpg, 426ec06d-61f7-4d84-8b27-d952743d9bab_1745464780487_2.jpg"
	debug_error_string = "UNKNOWN:Error received from peer  {created_time:"2025-04-24T03:19:40.504735367+00:00", grpc_status:2, grpc_message:"Unexpected <class \'minio.error.S3Error\'>: S3 operation failed; code: NoSuchKey, message: The specified key does not exist., resource: /profiles-images/426ec06d-61f7-4d84-8b27-d952743d9bab_1745464780472_0.jpg, 426ec06d-61f7-4d84-8b27-d952743d9bab_1745464780481_1.jpg, 426ec06d-61f7-4d84-8b27-d952743d9bab_1745464780487_2.jpg, request_id: 183922F851DDAF46, host_id: dd9025bab4ad464b049177c95eb6ebf374d3b3fd1af9251148b658df7ac2e3e8, bucket_name: profiles-images, object_name: 426ec06d-61f7-4d84-8b27-d952743d9bab_1745464780472_0.jpg, 426ec06d-61f7-4d84-8b27-d952743d9bab_1745464780481_1.jpg, 426ec06d-61f7-4d84-8b27-d952743d9bab_1745464780487_2.jpg"}"
>
2025-04-24 11:15:27,914 - [ERROR] -  src.handlers.menu - (menu.py).menu(38) - <_InactiveRpcError of RPC that terminated with:
	status = StatusCode.UNAVAILABLE
	details = "DNS resolution failed for profiles_service:1337: C-ares status is not ARES_SUCCESS qtype=AAAA name=profiles_service is_balancer=0: Could not contact DNS servers"
	debug_error_string = "UNKNOWN:Error received from peer  {grpc_message:"DNS resolution failed for profiles_service:1337: C-ares status is not ARES_SUCCESS qtype=AAAA name=profiles_service is_balancer=0: Could not contact DNS servers", grpc_status:14, created_time:"2025-04-24T11:15:27.913854749+00:00"}"
>
Traceback (most recent call last):
  File "/usr/src/dating/bot_service/src/handlers/menu.py", line 33, in menu
    profile_data = await profiles_connection.get_by_account_id(account_id)
                   ^^^^^^^^^^^^^^^^^^^^^^^^^^^^^^^^^^^^^^^^^^^^^^^^^^^^^^^
  File "/usr/src/dating/bot_service/src/api/grpc/connections/profiles.py", line 90, in get_by_account_id
    return self.stub.Get(profile_request)
           ^^^^^^^^^^^^^^^^^^^^^^^^^^^^^^
  File "/usr/local/lib/python3.12/site-packages/grpc/_channel.py", line 1181, in __call__
    return _end_unary_response_blocking(state, call, False, None)
           ^^^^^^^^^^^^^^^^^^^^^^^^^^^^^^^^^^^^^^^^^^^^^^^^^^^^^^
  File "/usr/local/lib/python3.12/site-packages/grpc/_channel.py", line 1006, in _end_unary_response_blocking
    raise _InactiveRpcError(state)  # pytype: disable=not-instantiable
    ^^^^^^^^^^^^^^^^^^^^^^^^^^^^^^
grpc._channel._InactiveRpcError: <_InactiveRpcError of RPC that terminated with:
	status = StatusCode.UNAVAILABLE
	details = "DNS resolution failed for profiles_service:1337: C-ares status is not ARES_SUCCESS qtype=AAAA name=profiles_service is_balancer=0: Could not contact DNS servers"
	debug_error_string = "UNKNOWN:Error received from peer  {grpc_message:"DNS resolution failed for profiles_service:1337: C-ares status is not ARES_SUCCESS qtype=AAAA name=profiles_service is_balancer=0: Could not contact DNS servers", grpc_status:14, created_time:"2025-04-24T11:15:27.913854749+00:00"}"
>
2025-04-24 11:15:53,541 - [ERROR] -  src.handlers.menu - (menu.py).menu(38) - <_InactiveRpcError of RPC that terminated with:
	status = StatusCode.UNAVAILABLE
	details = "DNS resolution failed for profiles_service:1337: C-ares status is not ARES_SUCCESS qtype=AAAA name=profiles_service is_balancer=0: Could not contact DNS servers"
	debug_error_string = "UNKNOWN:Error received from peer  {grpc_message:"DNS resolution failed for profiles_service:1337: C-ares status is not ARES_SUCCESS qtype=AAAA name=profiles_service is_balancer=0: Could not contact DNS servers", grpc_status:14, created_time:"2025-04-24T11:15:53.541410623+00:00"}"
>
Traceback (most recent call last):
  File "/usr/src/dating/bot_service/src/handlers/menu.py", line 33, in menu
    profile_data = await profiles_connection.get_by_account_id(account_id)
                   ^^^^^^^^^^^^^^^^^^^^^^^^^^^^^^^^^^^^^^^^^^^^^^^^^^^^^^^
  File "/usr/src/dating/bot_service/src/api/grpc/connections/profiles.py", line 90, in get_by_account_id
    return self.stub.Get(profile_request)
           ^^^^^^^^^^^^^^^^^^^^^^^^^^^^^^
  File "/usr/local/lib/python3.12/site-packages/grpc/_channel.py", line 1181, in __call__
    return _end_unary_response_blocking(state, call, False, None)
           ^^^^^^^^^^^^^^^^^^^^^^^^^^^^^^^^^^^^^^^^^^^^^^^^^^^^^^
  File "/usr/local/lib/python3.12/site-packages/grpc/_channel.py", line 1006, in _end_unary_response_blocking
    raise _InactiveRpcError(state)  # pytype: disable=not-instantiable
    ^^^^^^^^^^^^^^^^^^^^^^^^^^^^^^
grpc._channel._InactiveRpcError: <_InactiveRpcError of RPC that terminated with:
	status = StatusCode.UNAVAILABLE
	details = "DNS resolution failed for profiles_service:1337: C-ares status is not ARES_SUCCESS qtype=AAAA name=profiles_service is_balancer=0: Could not contact DNS servers"
	debug_error_string = "UNKNOWN:Error received from peer  {grpc_message:"DNS resolution failed for profiles_service:1337: C-ares status is not ARES_SUCCESS qtype=AAAA name=profiles_service is_balancer=0: Could not contact DNS servers", grpc_status:14, created_time:"2025-04-24T11:15:53.541410623+00:00"}"
>
2025-04-24 11:16:55,588 - [ERROR] -  src.handlers.menu - (menu.py).menu(38) - <_InactiveRpcError of RPC that terminated with:
	status = StatusCode.UNAVAILABLE
	details = "DNS resolution failed for profiles_service:1337: C-ares status is not ARES_SUCCESS qtype=A name=profiles_service is_balancer=0: Could not contact DNS servers"
	debug_error_string = "UNKNOWN:Error received from peer  {created_time:"2025-04-24T11:16:55.588351844+00:00", grpc_status:14, grpc_message:"DNS resolution failed for profiles_service:1337: C-ares status is not ARES_SUCCESS qtype=A name=profiles_service is_balancer=0: Could not contact DNS servers"}"
>
Traceback (most recent call last):
  File "/usr/src/dating/bot_service/src/handlers/menu.py", line 33, in menu
    profile_data = await profiles_connection.get_by_account_id(account_id)
                   ^^^^^^^^^^^^^^^^^^^^^^^^^^^^^^^^^^^^^^^^^^^^^^^^^^^^^^^
  File "/usr/src/dating/bot_service/src/api/grpc/connections/profiles.py", line 90, in get_by_account_id
    return self.stub.Get(profile_request)
           ^^^^^^^^^^^^^^^^^^^^^^^^^^^^^^
  File "/usr/local/lib/python3.12/site-packages/grpc/_channel.py", line 1181, in __call__
    return _end_unary_response_blocking(state, call, False, None)
           ^^^^^^^^^^^^^^^^^^^^^^^^^^^^^^^^^^^^^^^^^^^^^^^^^^^^^^
  File "/usr/local/lib/python3.12/site-packages/grpc/_channel.py", line 1006, in _end_unary_response_blocking
    raise _InactiveRpcError(state)  # pytype: disable=not-instantiable
    ^^^^^^^^^^^^^^^^^^^^^^^^^^^^^^
grpc._channel._InactiveRpcError: <_InactiveRpcError of RPC that terminated with:
	status = StatusCode.UNAVAILABLE
	details = "DNS resolution failed for profiles_service:1337: C-ares status is not ARES_SUCCESS qtype=A name=profiles_service is_balancer=0: Could not contact DNS servers"
	debug_error_string = "UNKNOWN:Error received from peer  {created_time:"2025-04-24T11:16:55.588351844+00:00", grpc_status:14, grpc_message:"DNS resolution failed for profiles_service:1337: C-ares status is not ARES_SUCCESS qtype=A name=profiles_service is_balancer=0: Could not contact DNS servers"}"
>
2025-04-26 00:49:28,347 - [ERROR] -  src.handlers.menu - (menu.py).menu(38) - <_InactiveRpcError of RPC that terminated with:
	status = StatusCode.UNKNOWN
	details = "Unexpected <class 'TypeError'>: 'GenderEnum' object cannot be interpreted as an integer"
	debug_error_string = "UNKNOWN:Error received from peer  {created_time:"2025-04-26T00:49:28.34671725+00:00", grpc_status:2, grpc_message:"Unexpected <class \'TypeError\'>: \'GenderEnum\' object cannot be interpreted as an integer"}"
>
Traceback (most recent call last):
  File "/usr/src/dating/bot_service/src/handlers/menu.py", line 33, in menu
    profile_data = await profiles_connection.get_by_account_id(account_id)
                   ^^^^^^^^^^^^^^^^^^^^^^^^^^^^^^^^^^^^^^^^^^^^^^^^^^^^^^^
  File "/usr/src/dating/bot_service/src/api/grpc/connections/profiles.py", line 90, in get_by_account_id
    return self.stub.Get(profile_request)
           ^^^^^^^^^^^^^^^^^^^^^^^^^^^^^^
  File "/usr/local/lib/python3.12/site-packages/grpc/_channel.py", line 1181, in __call__
    return _end_unary_response_blocking(state, call, False, None)
           ^^^^^^^^^^^^^^^^^^^^^^^^^^^^^^^^^^^^^^^^^^^^^^^^^^^^^^
  File "/usr/local/lib/python3.12/site-packages/grpc/_channel.py", line 1006, in _end_unary_response_blocking
    raise _InactiveRpcError(state)  # pytype: disable=not-instantiable
    ^^^^^^^^^^^^^^^^^^^^^^^^^^^^^^
grpc._channel._InactiveRpcError: <_InactiveRpcError of RPC that terminated with:
	status = StatusCode.UNKNOWN
	details = "Unexpected <class 'TypeError'>: 'GenderEnum' object cannot be interpreted as an integer"
	debug_error_string = "UNKNOWN:Error received from peer  {created_time:"2025-04-26T00:49:28.34671725+00:00", grpc_status:2, grpc_message:"Unexpected <class \'TypeError\'>: \'GenderEnum\' object cannot be interpreted as an integer"}"
>
2025-04-28 02:33:54,165 - [ERROR] -  src.handlers.menu - (menu.py).menu(37) - <_InactiveRpcError of RPC that terminated with:
	status = StatusCode.UNKNOWN
	details = "Unexpected <class 'minio.error.S3Error'>: S3 operation failed; code: NoSuchKey, message: The specified key does not exist., resource: /profiles-images/placeholder_image.jpg, request_id: 183A5ACB28869E4E, host_id: dd9025bab4ad464b049177c95eb6ebf374d3b3fd1af9251148b658df7ac2e3e8, bucket_name: profiles-images, object_name: placeholder_image.jpg"
	debug_error_string = "UNKNOWN:Error received from peer  {grpc_message:"Unexpected <class \'minio.error.S3Error\'>: S3 operation failed; code: NoSuchKey, message: The specified key does not exist., resource: /profiles-images/placeholder_image.jpg, request_id: 183A5ACB28869E4E, host_id: dd9025bab4ad464b049177c95eb6ebf374d3b3fd1af9251148b658df7ac2e3e8, bucket_name: profiles-images, object_name: placeholder_image.jpg", grpc_status:2, created_time:"2025-04-28T02:33:54.165262221+00:00"}"
>
Traceback (most recent call last):
  File "/usr/src/dating/bot_service/src/handlers/menu.py", line 32, in menu
    profile_data = await profiles_connection.get_by_account_id(account_id)
                   ^^^^^^^^^^^^^^^^^^^^^^^^^^^^^^^^^^^^^^^^^^^^^^^^^^^^^^^
  File "/usr/src/dating/bot_service/src/api/grpc/connections/profiles.py", line 93, in get_by_account_id
    return self.stub.Get(profile_request)
           ^^^^^^^^^^^^^^^^^^^^^^^^^^^^^^
  File "/usr/local/lib/python3.12/site-packages/grpc/_channel.py", line 1181, in __call__
    return _end_unary_response_blocking(state, call, False, None)
           ^^^^^^^^^^^^^^^^^^^^^^^^^^^^^^^^^^^^^^^^^^^^^^^^^^^^^^
  File "/usr/local/lib/python3.12/site-packages/grpc/_channel.py", line 1006, in _end_unary_response_blocking
    raise _InactiveRpcError(state)  # pytype: disable=not-instantiable
    ^^^^^^^^^^^^^^^^^^^^^^^^^^^^^^
grpc._channel._InactiveRpcError: <_InactiveRpcError of RPC that terminated with:
	status = StatusCode.UNKNOWN
	details = "Unexpected <class 'minio.error.S3Error'>: S3 operation failed; code: NoSuchKey, message: The specified key does not exist., resource: /profiles-images/placeholder_image.jpg, request_id: 183A5ACB28869E4E, host_id: dd9025bab4ad464b049177c95eb6ebf374d3b3fd1af9251148b658df7ac2e3e8, bucket_name: profiles-images, object_name: placeholder_image.jpg"
	debug_error_string = "UNKNOWN:Error received from peer  {grpc_message:"Unexpected <class \'minio.error.S3Error\'>: S3 operation failed; code: NoSuchKey, message: The specified key does not exist., resource: /profiles-images/placeholder_image.jpg, request_id: 183A5ACB28869E4E, host_id: dd9025bab4ad464b049177c95eb6ebf374d3b3fd1af9251148b658df7ac2e3e8, bucket_name: profiles-images, object_name: placeholder_image.jpg", grpc_status:2, created_time:"2025-04-28T02:33:54.165262221+00:00"}"
>
2025-04-28 02:37:42,641 - [ERROR] -  src.handlers.menu - (menu.py).menu(37) - <_InactiveRpcError of RPC that terminated with:
	status = StatusCode.UNKNOWN
	details = "Unexpected <class 'minio.error.S3Error'>: S3 operation failed; code: NoSuchKey, message: The specified key does not exist., resource: /profiles-images/placeholder_image.jpg, request_id: 183A5B005AC4AD5A, host_id: dd9025bab4ad464b049177c95eb6ebf374d3b3fd1af9251148b658df7ac2e3e8, bucket_name: profiles-images, object_name: placeholder_image.jpg"
	debug_error_string = "UNKNOWN:Error received from peer  {created_time:"2025-04-28T02:37:42.641488204+00:00", grpc_status:2, grpc_message:"Unexpected <class \'minio.error.S3Error\'>: S3 operation failed; code: NoSuchKey, message: The specified key does not exist., resource: /profiles-images/placeholder_image.jpg, request_id: 183A5B005AC4AD5A, host_id: dd9025bab4ad464b049177c95eb6ebf374d3b3fd1af9251148b658df7ac2e3e8, bucket_name: profiles-images, object_name: placeholder_image.jpg"}"
>
Traceback (most recent call last):
  File "/usr/src/dating/bot_service/src/handlers/menu.py", line 32, in menu
    profile_data = await profiles_connection.get_by_account_id(account_id)
                   ^^^^^^^^^^^^^^^^^^^^^^^^^^^^^^^^^^^^^^^^^^^^^^^^^^^^^^^
  File "/usr/src/dating/bot_service/src/api/grpc/connections/profiles.py", line 93, in get_by_account_id
    return self.stub.Get(profile_request)
           ^^^^^^^^^^^^^^^^^^^^^^^^^^^^^^
  File "/usr/local/lib/python3.12/site-packages/grpc/_channel.py", line 1181, in __call__
    return _end_unary_response_blocking(state, call, False, None)
           ^^^^^^^^^^^^^^^^^^^^^^^^^^^^^^^^^^^^^^^^^^^^^^^^^^^^^^
  File "/usr/local/lib/python3.12/site-packages/grpc/_channel.py", line 1006, in _end_unary_response_blocking
    raise _InactiveRpcError(state)  # pytype: disable=not-instantiable
    ^^^^^^^^^^^^^^^^^^^^^^^^^^^^^^
grpc._channel._InactiveRpcError: <_InactiveRpcError of RPC that terminated with:
	status = StatusCode.UNKNOWN
	details = "Unexpected <class 'minio.error.S3Error'>: S3 operation failed; code: NoSuchKey, message: The specified key does not exist., resource: /profiles-images/placeholder_image.jpg, request_id: 183A5B005AC4AD5A, host_id: dd9025bab4ad464b049177c95eb6ebf374d3b3fd1af9251148b658df7ac2e3e8, bucket_name: profiles-images, object_name: placeholder_image.jpg"
	debug_error_string = "UNKNOWN:Error received from peer  {created_time:"2025-04-28T02:37:42.641488204+00:00", grpc_status:2, grpc_message:"Unexpected <class \'minio.error.S3Error\'>: S3 operation failed; code: NoSuchKey, message: The specified key does not exist., resource: /profiles-images/placeholder_image.jpg, request_id: 183A5B005AC4AD5A, host_id: dd9025bab4ad464b049177c95eb6ebf374d3b3fd1af9251148b658df7ac2e3e8, bucket_name: profiles-images, object_name: placeholder_image.jpg"}"
>
